Python 3.10.7 (v3.10.7:6cc6b13308, Sep  5 2022, 14:02:52) [Clang 13.0.0 (clang-1300.0.29.30)] on darwin
Type "help", "copyright", "credits" or "license()" for more information.

= RESTART: /Users/rajroshan/Downloads/6 semester copy/Ankeev sir/Big Data/BIG_DATA PART 2 LABS/lab5.py
14.444444444444445

= RESTART: /Users/rajroshan/Downloads/6 semester copy/Ankeev sir/Big Data/BIG_DATA PART 2 LABS/lab5.py
14.444444444444445
14.444444444444445
13
26

= RESTART: /Users/rajroshan/Downloads/6 semester copy/Ankeev sir/Big Data/BIG_DATA PART 2 LABS/lab5.py
14.444444444444445
14.444444444444445
13
26
10.369560153534854
18.155195154861627
import stats
Traceback (most recent call last):
  File "<pyshell#0>", line 1, in <module>
    import stats
ModuleNotFoundError: No module named 'stats'
import statistics
help(stats)
Traceback (most recent call last):
  File "<pyshell#2>", line 1, in <module>
    help(stats)
NameError: name 'stats' is not defined
help(stats())
Traceback (most recent call last):
  File "<pyshell#3>", line 1, in <module>
    help(stats())
NameError: name 'stats' is not defined

= RESTART: /Users/rajroshan/Downloads/6 semester copy/Ankeev sir/Big Data/BIG_DATA PART 2 LABS/lab5.py
14.444444444444445
14.444444444444445
13
26
10.369560153534854
18.155195154861627
Traceback (most recent call last):
  File "/Users/rajroshan/Downloads/6 semester copy/Ankeev sir/Big Data/BIG_DATA PART 2 LABS/lab5.py", line 21, in <module>
    stats_sampleP = st.stats(sampleP)
AttributeError: module 'statistics' has no attribute 'stats'

= RESTART: /Users/rajroshan/Downloads/6 semester copy/Ankeev sir/Big Data/BIG_DATA PART 2 LABS/lab5.py
14.444444444444445
14.444444444444445
13
26
10.369560153534854
18.155195154861627
Traceback (most recent call last):
  File "/Users/rajroshan/Downloads/6 semester copy/Ankeev sir/Big Data/BIG_DATA PART 2 LABS/lab5.py", line 21, in <module>
    stats_sampleP = st.stats(sampleP)
AttributeError: module 'statistics' has no attribute 'stats'

= RESTART: /Users/rajroshan/Downloads/6 semester copy/Ankeev sir/Big Data/BIG_DATA PART 2 LABS/lab5.py
14.444444444444445
14.444444444444445
13
26
10.369560153534854
18.155195154861627
Traceback (most recent call last):
  File "/Users/rajroshan/Downloads/6 semester copy/Ankeev sir/Big Data/BIG_DATA PART 2 LABS/lab5.py", line 31, in <module>
    print(syyMeasure)
NameError: name 'syyMeasure' is not defined. Did you mean: 'symmMeasure'?

= RESTART: /Users/rajroshan/Downloads/6 semester copy/Ankeev sir/Big Data/BIG_DATA PART 2 LABS/lab5.py
14.444444444444445
14.444444444444445
13
26
10.369560153534854
18.155195154861627
True
None

= RESTART: /Users/rajroshan/Downloads/6 semester copy/Ankeev sir/Big Data/BIG_DATA PART 2 LABS/lab5.py
14.444444444444445
14.444444444444445
13
26
10.369560153534854
18.155195154861627

= RESTART: /Users/rajroshan/Downloads/6 semester copy/Ankeev sir/Big Data/BIG_DATA PART 2 LABS/lab5.py
14.444444444444445
14.444444444444445
13
26
10.369560153534854
18.155195154861627
True
None

= RESTART: /Users/rajroshan/Downloads/6 semester copy/Ankeev sir/Big Data/BIG_DATA PART 2 LABS/lab5.py
14.444444444444445
14.444444444444445
13
26
10.369560153534854
18.155195154861627
True
None

= RESTART: /Users/rajroshan/Downloads/6 semester copy/Ankeev sir/Big Data/BIG_DATA PART 2 LABS/lab5.py
14.444444444444445
14.444444444444445
13
26
10.369560153534854
18.155195154861627
True
None
True
None

= RESTART: /Users/rajroshan/Downloads/6 semester copy/Ankeev sir/Big Data/BIG_DATA PART 2 LABS/lab5.py
14.444444444444445
14.444444444444445
13
26
10.369560153534854
18.155195154861627
True
None
True
None
Traceback (most recent call last):
  File "/Users/rajroshan/Downloads/6 semester copy/Ankeev sir/Big Data/BIG_DATA PART 2 LABS/lab5.py", line 45, in <module>
    CorrCoffPQ = st.corrCoeff(sampleP,sampleQ)
AttributeError: module 'statistics' has no attribute 'corrCoeff'

= RESTART: /Users/rajroshan/Downloads/6 semester copy/Ankeev sir/Big Data/BIG_DATA PART 2 LABS/lab5.py
14.444444444444445
14.444444444444445
13
26
10.369560153534854
18.155195154861627
True
None
True
None
0.826348121005344

= RESTART: /Users/rajroshan/Downloads/6 semester copy/Ankeev sir/Big Data/BIG_DATA PART 2 LABS/task 1.py

= RESTART: /Users/rajroshan/Downloads/6 semester copy/Ankeev sir/Big Data/BIG_DATA PART 2 LABS/task 1.py
Traceback (most recent call last):
  File "/Users/rajroshan/Downloads/6 semester copy/Ankeev sir/Big Data/BIG_DATA PART 2 LABS/task 1.py", line 11, in <module>
    print(generate_random_integer())
NameError: name 'generate_random_integer' is not defined. Did you mean: 'generate_random_integers'?

= RESTART: /Users/rajroshan/Downloads/6 semester copy/Ankeev sir/Big Data/BIG_DATA PART 2 LABS/task 1.py
(66, 24, -42)

= RESTART: /Users/rajroshan/Downloads/6 semester copy/Ankeev sir/Big Data/BIG_DATA PART 2 LABS/task 1.py
(-21, 33, 4)

= RESTART: /Users/rajroshan/Downloads/6 semester copy/Ankeev sir/Big Data/BIG_DATA PART 2 LABS/task2.py
[54, 26, -96]

= RESTART: /Users/rajroshan/Downloads/6 semester copy/Ankeev sir/Big Data/BIG_DATA PART 2 LABS/task2.py
([75, 40, 61], 75, 40, 61)

= RESTART: /Users/rajroshan/Downloads/6 semester copy/Ankeev sir/Big Data/BIG_DATA PART 2 LABS/task2.py
(-72, 76, -98)

= RESTART: /Users/rajroshan/Downloads/6 semester copy/Ankeev sir/Big Data/BIG_DATA PART 2 LABS/task2.py
(-43, -23, -82)
Traceback (most recent call last):
  File "/Users/rajroshan/Downloads/6 semester copy/Ankeev sir/Big Data/BIG_DATA PART 2 LABS/task2.py", line 9, in <module>
    print(a)
NameError: name 'a' is not defined

= RESTART: /Users/rajroshan/Downloads/6 semester copy/Ankeev sir/Big Data/BIG_DATA PART 2 LABS/task2.py
(80, -42, -6)

= RESTART: /Users/rajroshan/Downloads/6 semester copy/Ankeev sir/Big Data/BIG_DATA PART 2 LABS/task2.py
(44, 64, 97)
Traceback (most recent call last):
  File "/Users/rajroshan/Downloads/6 semester copy/Ankeev sir/Big Data/BIG_DATA PART 2 LABS/task2.py", line 24, in <module>
    solve_quad_eq(random_number())
TypeError: solve_quad_eq() missing 2 required positional arguments: 'b' and 'c'

= RESTART: /Users/rajroshan/Downloads/6 semester copy/Ankeev sir/Big Data/BIG_DATA PART 2 LABS/task2.py
(-79, 98, -76)
Traceback (most recent call last):
  File "/Users/rajroshan/Downloads/6 semester copy/Ankeev sir/Big Data/BIG_DATA PART 2 LABS/task2.py", line 27, in <module>
    solve_quad_eq(random_number())
TypeError: solve_quad_eq() missing 2 required positional arguments: 'b' and 'c'

= RESTART: /Users/rajroshan/Downloads/6 semester copy/Ankeev sir/Big Data/BIG_DATA PART 2 LABS/task2.py
(80, -30, -73)

= RESTART: /Users/rajroshan/Downloads/6 semester copy/Ankeev sir/Big Data/BIG_DATA PART 2 LABS/task2.py
(-94, -30, 66)
absence of real Root in the equation

= RESTART: /Users/rajroshan/Downloads/6 semester copy/Ankeev sir/Big Data/BIG_DATA PART 2 LABS/task2.py
(-49, 9, 16)
Traceback (most recent call last):
  File "/Users/rajroshan/Downloads/6 semester copy/Ankeev sir/Big Data/BIG_DATA PART 2 LABS/task2.py", line 27, in <module>
    print(solve_quad_eq(random_number))
TypeError: solve_quad_eq() missing 2 required positional arguments: 'b' and 'c'

= RESTART: /Users/rajroshan/Downloads/6 semester copy/Ankeev sir/Big Data/BIG_DATA PART 2 LABS/task2.py
(92, -70, 76)
Traceback (most recent call last):
  File "/Users/rajroshan/Downloads/6 semester copy/Ankeev sir/Big Data/BIG_DATA PART 2 LABS/task2.py", line 27, in <module>
    print(solve_quad_eq(random_number,random_number,random_number))
  File "/Users/rajroshan/Downloads/6 semester copy/Ankeev sir/Big Data/BIG_DATA PART 2 LABS/task2.py", line 14, in solve_quad_eq
    D = b**2-4*a*c
TypeError: unsupported operand type(s) for ** or pow(): 'function' and 'int'

= RESTART: /Users/rajroshan/Downloads/6 semester copy/Ankeev sir/Big Data/BIG_DATA PART 2 LABS/task2.py
(-31, 3, -24)
Traceback (most recent call last):
  File "/Users/rajroshan/Downloads/6 semester copy/Ankeev sir/Big Data/BIG_DATA PART 2 LABS/task2.py", line 27, in <module>
    print(solve_quad_eq(random_number()))
TypeError: solve_quad_eq() missing 2 required positional arguments: 'b' and 'c'

= RESTART: /Users/rajroshan/Downloads/6 semester copy/Ankeev sir/Big Data/BIG_DATA PART 2 LABS/task2.py
(-39, -38, 70)
Traceback (most recent call last):
  File "/Users/rajroshan/Downloads/6 semester copy/Ankeev sir/Big Data/BIG_DATA PART 2 LABS/task2.py", line 27, in <module>
    print(solve_quad_eq(random_number))
TypeError: solve_quad_eq() missing 2 required positional arguments: 'b' and 'c'

= RESTART: /Users/rajroshan/Downloads/6 semester copy/Ankeev sir/Big Data/BIG_DATA PART 2 LABS/task2.py
(-35, 85, 80)
Traceback (most recent call last):
  File "/Users/rajroshan/Downloads/6 semester copy/Ankeev sir/Big Data/BIG_DATA PART 2 LABS/task2.py", line 27, in <module>
    print(solve_quad_eq(*random_number))
TypeError: __main__.solve_quad_eq() argument after * must be an iterable, not function

= RESTART: /Users/rajroshan/Downloads/6 semester copy/Ankeev sir/Big Data/BIG_DATA PART 2 LABS/check code.py
(-87, -68, 15)
(-0.017201257961740716, 0.8808376215981044)

= RESTART: /Users/rajroshan/Downloads/6 semester copy/Ankeev sir/Big Data/BIG_DATA PART 2 LABS/check code.py
(-9, 81, -60)
absence of real roots in the equation

= RESTART: /Users/rajroshan/Downloads/6 semester copy/Ankeev sir/Big Data/BIG_DATA PART 2 LABS/task2.py
(-26, -68, 15)
Traceback (most recent call last):
  File "/Users/rajroshan/Downloads/6 semester copy/Ankeev sir/Big Data/BIG_DATA PART 2 LABS/task2.py", line 27, in <module>
    print(solve_quad_eq(*random_number))
TypeError: __main__.solve_quad_eq() argument after * must be an iterable, not function

= RESTART: /Users/rajroshan/Downloads/6 semester copy/Ankeev sir/Big Data/BIG_DATA PART 2 LABS/task2.py
(99, -61, 47)
Traceback (most recent call last):
  File "/Users/rajroshan/Downloads/6 semester copy/Ankeev sir/Big Data/BIG_DATA PART 2 LABS/task2.py", line 27, in <module>
    print(solve_quad_eq(random_number))
TypeError: solve_quad_eq() missing 2 required positional arguments: 'b' and 'c'

= RESTART: /Users/rajroshan/Downloads/6 semester copy/Ankeev sir/Big Data/BIG_DATA PART 2 LABS/task2.py
(-98, -99, -42)
Traceback (most recent call last):
  File "/Users/rajroshan/Downloads/6 semester copy/Ankeev sir/Big Data/BIG_DATA PART 2 LABS/task2.py", line 27, in <module>
    print(solve_quad_eq(random_number()))
TypeError: solve_quad_eq() missing 2 required positional arguments: 'b' and 'c'
>>> 
= RESTART: /Users/rajroshan/Downloads/6 semester copy/Ankeev sir/Big Data/BIG_DATA PART 2 LABS/task2.py
(-90, -74, -94)
Traceback (most recent call last):
  File "/Users/rajroshan/Downloads/6 semester copy/Ankeev sir/Big Data/BIG_DATA PART 2 LABS/task2.py", line 27, in <module>
    print(solve_quad_eq(random_number()))
TypeError: solve_quad_eq() missing 2 required positional arguments: 'b' and 'c'
>>> 
= RESTART: /Users/rajroshan/Downloads/6 semester copy/Ankeev sir/Big Data/BIG_DATA PART 2 LABS/task2.py
(57, 34, 8)
(499696.0, -504880.0)
>>> 
= RESTART: /Users/rajroshan/Downloads/6 semester copy/Ankeev sir/Big Data/BIG_DATA PART 2 LABS/task2.py
(69, 68, 60)
(-63720.0, 66690.0)
>>> 
= RESTART: /Users/rajroshan/Downloads/6 semester copy/Ankeev sir/Big Data/BIG_DATA PART 2 LABS/task2.py
(53, -100, -7)
Traceback (most recent call last):
  File "/Users/rajroshan/Downloads/6 semester copy/Ankeev sir/Big Data/BIG_DATA PART 2 LABS/task2.py", line 27, in <module>
    print(solve_quad_eq(random_number()))
TypeError: solve_quad_eq() missing 2 required positional arguments: 'b' and 'c'
>>> 
= RESTART: /Users/rajroshan/Downloads/6 semester copy/Ankeev sir/Big Data/BIG_DATA PART 2 LABS/task2.py
(-49, -72, 8)
absence of real Root in the equation
>>> 
= RESTART: /Users/rajroshan/Downloads/6 semester copy/Ankeev sir/Big Data/BIG_DATA PART 2 LABS/task2.py
(93, 18, -32)
(-9886.25, 7741.25)
>>> 
= RESTART: /Users/rajroshan/Downloads/6 semester copy/Ankeev sir/Big Data/BIG_DATA PART 2 LABS/task2.py
[58, 19, 1]
(37632.0, -32256.0)
